Workbook

Sheet Summary
A1: EPPIB Strategic Investment Plan
A2: Model status | B2: =Checks!B4 -> ALL CHECKS PASS | D2: Method | E2: =Methods!B2 -> Robust MVO
A4: 1. Strategic asset allocation | H4: 2. Brief compliance
A5: Asset class | B5: Current | C5: Benchmark | D5: Recommended | E5: Change vs current | F5: Trade (A$m) | H5: Requirement | I5: Limit | J5: Recommended | K5: Status
A6: Australian Equities | B6: =Portfolio!C6 -> 0.4 | C6: =Portfolio!D6 -> 0.25 | D6: =Portfolio!E6 -> 0.2738 | E6: =Portfolio!I6 -> -0.1262 | F6: =Portfolio!J6 -> -378.6 | H6: (a) Return: bond yield + 4% (compound) | I6: =Inputs!$B$25 -> 0.08988 | J6: =Risk!N58-Risk!M58^2/2 -> 0.066959679 | K6: =IF(J6>=I6,"MET",IF(Forecast!G18<I6,"MAX FEASIBLE","NOT MET")) -> MAX FEASIBLE
A7: World Equities | B7: =Portfolio!C7 -> 0.2 | C7: =Portfolio!D7 -> 0.24 | D7: =Portfolio!E7 -> 0.279 | E7: =Portfolio!I7 -> 0.079 | F7: =Portfolio!J7 -> 237 | H7: (b) Minimise risk: volatility vs current fund | I7: =Risk!M56 -> 0.083833964 | J7: =Risk!M58 -> 0.078389128 | K7: =IF(J7<=I7,"MET","NOT MET") -> MET
A8: Emerging Markets | B8: =Portfolio!C8 -> 0 | C8: =Portfolio!D8 -> 0.03 | D8: =Portfolio!E8 -> 0.0672 | E8: =Portfolio!I8 -> 0.0672 | F8: =Portfolio!J8 -> 201.6 | H8: (c) 5-year loss probability, bootstrap | I8: =Inputs!$B$28 -> 0.25 | J8: =Bootstrap!D6 -> 0.073 | K8: =IF(J8<=I8,"MET","NOT MET") -> MET
A9: Listed Property | B9: =Portfolio!C9 -> 0.1 | C9: =Portfolio!D9 -> 0.07 | D9: =Portfolio!E9 -> 0.0867 | E9: =Portfolio!I9 -> -0.0133 | F9: =Portfolio!J9 -> -39.9 | H9: (c) 5-year loss probability, normal | I9: =Inputs!$B$28 -> 0.25 | J9: =Bootstrap!D7 -> 0.028064013 | K9: =IF(J9<=I9,"MET","NOT MET") -> MET
A10: Commodities | B10: =Portfolio!C10 -> 0 | C10: =Portfolio!D10 -> 0.02 | D10: =Portfolio!E10 -> 0.0244 | E10: =Portfolio!I10 -> 0.0244 | F10: =Portfolio!J10 -> 73.2 | H10: (d) Tracking error, parametric | I10: =Inputs!$B$27 -> 0.015 | J10: =Risk!O58 -> 0.011002382 | K10: =IF(J10<=I10,"MET","NOT MET") -> MET
A11: Direct Property | B11: =Portfolio!C11 -> 0 | C11: =Portfolio!D11 -> 0.05 | D11: =Portfolio!E11 -> 0 | E11: =Portfolio!I11 -> 0 | F11: =Portfolio!J11 -> 0 | H11: (d) Tracking error, bootstrap | I11: =Inputs!$B$27 -> 0.015 | J11: =Bootstrap!D12 -> 0.011821602 | K11: =IF(J11<=I11,"MET","NOT MET") -> MET
A12: Hedge Funds | B12: =Portfolio!C12 -> 0 | C12: =Portfolio!D12 -> 0.03 | D12: =Portfolio!E12 -> 0 | E12: =Portfolio!I12 -> 0 | F12: =Portfolio!J12 -> 0 | H12: (e) Equity minimum | I12: =Inputs!$B$31 -> 0.42 | J12: =Portfolio!B34 -> 0.62 | K12: =IF(J12>=I12-0.000001,"MET","NOT MET") -> MET
A13: Private Equity | B13: =Portfolio!C13 -> 0 | C13: =Portfolio!D13 -> 0.03 | D13: =Portfolio!E13 -> 0 | E13: =Portfolio!I13 -> 0 | F13: =Portfolio!J13 -> 0 | H13: (e) Equity maximum | I13: =Inputs!$B$32 -> 0.62 | J13: =Portfolio!B34 -> 0.62 | K13: =IF(J13<=I13+0.000001,"MET","NOT MET") -> MET
A14: Australian Fixed Income | B14: =Portfolio!C14 -> 0.15 | C14: =Portfolio!D14 -> 0.14 | D14: =Portfolio!E14 -> 0.12 | E14: =Portfolio!I14 -> -0.03 | F14: =Portfolio!J14 -> -90 | H14: (e) Illiquid maximum | I14: =Inputs!$B$33 -> 0.3 | J14: =Portfolio!B35 -> 0 | K14: =IF(J14<=I14,"MET","NOT MET") -> MET
A15: World Fixed Income | B15: =Portfolio!C15 -> 0.08 | C15: =Portfolio!D15 -> 0.11 | D15: =Portfolio!E15 -> 0.1289 | E15: =Portfolio!I15 -> 0.0489 | F15: =Portfolio!J15 -> 146.7 | H15: (e) Cash minimum | I15: =Inputs!$B$34 -> 0.02 | J15: =Portfolio!B36 -> 0.02 | K15: =IF(J15>=I15,"MET","NOT MET") -> MET
A16: Cash | B16: =Portfolio!C16 -> 0.07 | C16: =Portfolio!D16 -> 0.03 | D16: =Portfolio!E16 -> 0.02 | E16: =Portfolio!I16 -> -0.05 | F16: =Portfolio!J16 -> -150 | H16: (e) No short sales or borrowing | I16: =0 -> 0 | J16: =MIN(Portfolio!E6:E16) -> 0 | K16: =IF(J16>=I16-0.000001,"MET","NOT MET") -> MET
A17: Total | B17: =SUM(B6:B16) -> 1 | C17: =SUM(C6:C16) -> 1 | D17: =SUM(D6:D16) -> 1 | E17: =SUM(E6:E16) -> 0 | F17: =SUM(F6:F16) -> 0
A18: One-way turnover | D18: =SUMPRODUCT(ABS(Portfolio!I6:I16))/2 -> 0.2195
A19: Change in fees (A$m p.a.) | D19: =(SUMPRODUCT(Portfolio!E6:E16,Inputs!$D$5:$D$15)-SUMPRODUCT(Portfolio!C6:C16,Inputs!$D$5:$D$15))*Inputs!$B$22 -> 0.6333
A22: 3. Expected outcomes (net of fees) | H22: 4. Stress tests (portfolio return)
A23: Metric | B23: Current | C23: Benchmark | D23: Recommended | E23: Change vs current | H23: Scenario | I23: Current | J23: Benchmark | K23: Recommended
A24: Expected return, compound (p.a.) | B24: =Risk!N56-Risk!M56^2/2 -> 0.066110548 | C24: =Risk!N57-Risk!M57^2/2 -> 0.063796067 | D24: =Risk!N58-Risk!M58^2/2 -> 0.066959679 | E24: =D24-B24 -> 0.00084913061 | H24: Global financial crisis | I24: =Stress!B26 -> -0.24167171 | J24: =Stress!B27 -> -0.19300089 | K24: =Stress!B28 -> -0.2350248
A25: Volatility (p.a.) | B25: =Risk!M56 -> 0.083833964 | C25: =Risk!M57 -> 0.070134112 | D25: =Risk!M58 -> 0.078389128 | E25: =D25-B25 -> -0.005444836 | H25: COVID shock | I25: =Stress!C26 -> -0.12092703 | J25: =Stress!C27 -> -0.091806485 | K25: =Stress!C28 -> -0.10748236
A26: Tracking error, parametric | B26: =Risk!O56 -> 0.021585026 | C26: =Risk!O57 -> 0 | D26: =Risk!O58 -> 0.011002382 | E26: =D26-B26 -> -0.010582644 | H26: Inflation sell-off (2022) | I26: =Stress!D26 -> -0.072754437 | J26: =Stress!D27 -> -0.072610798 | K26: =Stress!D28 -> -0.075405586
A27: Tracking error, bootstrap | B27: =Bootstrap!B12 -> 0.0156484 | C27: =Bootstrap!C12 -> 0 | D27: =Bootstrap!D12 -> 0.011821602 | E27: =D27-B27 -> -0.0038267977 | H27: US$150 oil (central case) | I27: =Stress!E26 -> -0.082609308 | J27: =Stress!E27 -> -0.073910247 | K27: =Stress!E28 -> -0.08363891
A28: 5-year loss probability, bootstrap | B28: =Bootstrap!B6 -> 0.077 | C28: =Bootstrap!C6 -> 0.062 | D28: =Bootstrap!D6 -> 0.073 | E28: =D28-B28 -> -0.004
A29: Median 5-year cumulative return | B29: =Bootstrap!B9 -> 0.39414359 | C29: =Bootstrap!C9 -> 0.3749255 | D29: =Bootstrap!D9 -> 0.39501952 | E29: =D29-B29 -> 0.00087593938 | H29: 5. Oil: 5-year regression on oil (log) change
A30: Management fee (p.a.) | B30: =SUMPRODUCT(Portfolio!C6:C16,Inputs!$D$5:$D$15) -> 0.00112 | C30: =SUMPRODUCT(Portfolio!D6:D16,Inputs!$D$5:$D$15) -> 0.00338 | D30: =SUMPRODUCT(Portfolio!E6:E16,Inputs!$D$5:$D$15) -> 0.0013311 | E30: =D30-B30 -> 0.0002111 | H30: Series | I30: Beta | J30: t-stat (adj.) | K30: R-squared
H31: US equities | I31: =Oil!C13 -> -0.22998127 | J31: =Oil!E13 -> -1.5542333 | K31: =Oil!F13 -> 0.1858332
H32: Australian equities | I32: =Oil!C16 -> 0.087571808 | J32: =Oil!E16 -> 0.57873507 | K32: =Oil!F16 -> 0.044450857
H33: AU 3-month rate (pp) | I33: =Oil!C19 -> 2.6117925 | J33: =Oil!E19 -> 1.4569815 | K33: =Oil!F19 -> 0.1670686
H34: Likelihood: 12-month rise of this size | K34: =Oil!B51 -> 0.10656934
H36: 6. Out-of-sample (2016-26) and sensitivity
H37: Measure | I37: Robust | J37: Naive MVO | K37: Current
H38: Realised return, annualised | I38: =Validation!B47 -> 0.087743665 | J38: =Validation!C47 -> 0.067680847 | K38: =Validation!D47 -> 0.077761951
H39: Realised volatility | I39: =Validation!B49 -> 0.081380343 | J39: =Validation!C49 -> 0.066488181 | K39: =Validation!D49 -> 0.085331791
H40: Return per unit of risk | I40: =Validation!B50 -> 1.0781924 | J40: =Validation!C50 -> 1.017938 | K40: =Validation!D50 -> 0.91128933
H41: Max weight move (sensitivity) | K41: =MAX(Validation!E58:E60) -> 0.0346
H43: 7. Track record: rolling 5-year windows since 2011
H44: Measure | I44: Current | J44: Benchmark | K44: Recommended
H45: Met return target | I45: ='Track record'!M13 -> 0.68852459 | J45: ='Track record'!N13 -> 0.68852459 | K45: ='Track record'!O13 -> 0.7704918
...

Sheet Report figures
A1: Report figures
A3: Figure index
A4: Figure | B4: Title | F4: Source tab
A5: Figure 1 | B5: Risk-return opportunity set | F5: Validation, Methods
A6: Figure 2 | B6: Strategic asset allocation | F6: Portfolio
A7: Figure 3 | B7: Fund performance since 2006 | F7: Quarterly returns, RBA 5Y yield
A8: Figure 4 | B8: Annualised returns to March 2026 | F8: Track record
A9: Figure 5 | B9: Stress tests | F9: Stress
A10: Figure 6 | B10: Five-year outcomes (forecast-adjusted bootstrap) | F10: Bootstrap
A11: Figure 7 | B11: How far the return target is out of reach | F11: Portfolio
A12: Figure 8 | B12: US$150 oil: estimates by method | F12: Oil
A13: Figure 9 | B13: Oil and equity returns by horizon | F13: Oil
A14: Figure 10 | B14: Rolling 5-year return against the target | F14: Track record
A15: Figure 11 | B15: Portfolio construction methods | F15: Methods
... A19: Figure 15 | B19: Attribution of active return | F19: Performance
A20: Figure 1. Risk-return opportunity set | N20: Chart data, figure 1
N21: Point | O21: Vol (no TE limit) | P21: Return (no TE limit) | Q21: Vol (TE limit) | R21: Return (TE limit)
N22: Point 1 | O22: =Validation!B125 -> 0.046682076 | P22: =Validation!B124 -> 0.060410992 | Q22: =Validation!B143 -> 0.059513407 | R22: =Validation!B142 -> 0.063481367
N23: Point 2 | O23: =Validation!C125 -> 0.047504271 | P23: =Validation!C124 -> 0.061713833 | Q23: =Validation!C143 -> 0.059815896 | R23: =Validation!C142 -> 0.064209885
N24: Point 3 | O24: =Validation!D125 -> 0.050686493 | P24: =Validation!D124 -> 0.06301402 | Q24: =Validation!D143 -> 0.060560834 | R24: =Validation!D142 -> 0.064938609
N25: Point 4 | O25: =Validation!E125 -> 0.054921807 | P25: =Validation!E124 -> 0.064316815 | Q25: =Validation!E143 -> 0.061684335 | R25: =Validation!E142 -> 0.065664485
N26: Point 5 | O26: =Validation!F125 -> 0.059449541 | P26: =Validation!F124 -> 0.065618698 | Q26: =Validation!F143 -> 0.06326355 | R26: =Validation!F142 -> 0.066392561
N27: Point 6 | O27: =Validation!G125 -> 0.064206719 | P27: =Validation!G124 -> 0.066922303 | Q27: =Validation!G143 -> 0.065427375 | R27: =Validation!G142 -> 0.067119175
N28: Point 7 | O28: =Validation!H125 -> 0.069215546 | P28: =Validation!H124 -> 0.068223746 | Q28: =Validation!H143 -> 0.06800267 | R28: =Validation!H142 -> 0.067848386
N29: Point 8 | O29: =Validation!I125 -> 0.074801788 | P29: =Validation!I124 -> 0.069526202 | Q29: =Validation!I143 -> 0.070952573 | R29: =Validation!I142 -> 0.068574794
N30: Point 9 | O30: =Validation!J125 -> 0.080501525 | P30: =Validation!J124 -> 0.070829045 | Q30: =Validation!J143 -> 0.074195142 | R30: =Validation!J142 -> 0.06930514
N31: Point 10 | O31: =Validation!K125 -> 0.090059124 | P31: =Validation!K124 -> 0.072131518 | Q31: =Validation!K143 -> 0.078389128 | R31: =Validation!K142 -> 0.070032106
N32: Portfolio | O32: Volatility | P32: Expected return
N33: Current fund | O33: =Risk!M56 -> 0.083833964 | P33: =Risk!N56 -> 0.069624615
N34: Benchmark | O34: =Risk!M57 -> 0.070134112 | P34: =Risk!N57 -> 0.066255464
N35: Recommended | O35: =Risk!M58 -> 0.078389128 | P35: =Risk!N58 -> 0.070032106
N36: Sample MVO | O36: =Methods!C23 -> 0.078033813 | P36: =Methods!B23 -> 0.069911884
N37: Resampled MVO | O37: =Methods!C24 -> 0.074319311 | P37: =Methods!B24 -> 0.06807754
N38: Minimum variance | O38: =Methods!C25 -> 0.059513407 | P38: =Methods!B25 -> 0.063481367
N39: Risk parity | O39: =Methods!C26 -> 0.066508938 | P39: =Methods!B26 -> 0.066570324
A46: Figure 2. Strategic asset allocation | N46: Chart data, figure 2
N47: Asset class | O47: Current fund | P47: Benchmark | Q47: Recommended
N48: Australian Equities | O48: =Summary!B6 -> 0.4 | P48: =Summary!C6 -> 0.25 | Q48: =Summary!D6 -> 0.2738
N49: World Equities | O49: =Summary!B7 -> 0.2 | P49: =Summary!C7 -> 0.24 | Q49: =Summary!D7 -> 0.279
N50: Emerging Markets | O50: =Summary!B8 -> 0 | P50: =Summary!C8 -> 0.03 | Q50: =Summary!D8 -> 0.0672
...

Sheet Inputs
A1: Inputs
A3: 1. Asset classes (linked to Fund balance sheet and Fee schedule)
A4: Asset class | B4: Current fund | C4: Benchmark | D4: Fee (p.a.) | E4: Lower bound | F4: Upper bound | G4: Equity (1/0) | H4: Illiquid (1/0) | J4: Blue = input
A5: Australian Equities | B5: =N('Fund balance sheet'!C7) -> 0.4 | C5: =N('Fund balance sheet'!D7) -> 0.25 | D5: ='Fee schedule'!B6 -> 0.001 | E5: 0.15 | F5: 0.35 | G5: 1 | H5: 0 | J5: Black = formula
A6: World Equities | B6: =N('Fund balance sheet'!C8) -> 0.2 | C6: =N('Fund balance sheet'!D8) -> 0.24 | D6: ='Fee schedule'!B7 -> 0.0015 | E6: 0.15 | F6: 0.35 | G6: 1 | H6: 0 | J6: Yellow = Solver decision cell
A7: Emerging Markets | B7: =N('Fund balance sheet'!C9) -> 0 | C7: =N('Fund balance sheet'!D9) -> 0.03 | D7: ='Fee schedule'!B8 -> 0.002 | E7: 0 | F7: 0.08 | G7: 1 | H7: 0
A8: Listed Property | B8: =N('Fund balance sheet'!C19) -> 0.1 | C8: =N('Fund balance sheet'!D19) -> 0.07 | D8: ='Fee schedule'!B9 -> 0.0015 | E8: 0 | F8: 0.12 | G8: 0 | H8: 0
A9: Commodities | B9: =N('Fund balance sheet'!C26) -> 0 | C9: =N('Fund balance sheet'!D26) -> 0.02 | D9: ='Fee schedule'!B17 -> 0.0025 | E9: 0 | F9: 0.08 | G9: 0 | H9: 0
A10: Direct Property | B10: =N('Fund balance sheet'!C20) -> 0 | C10: =N('Fund balance sheet'!D20) -> 0.05 | D10: ='Fee schedule'!B14 -> 0.012 | E10: 0 | F10: 0.1 | G10: 0 | H10: 1
A11: Hedge Funds | B11: =N('Fund balance sheet'!C24) -> 0 | C11: =N('Fund balance sheet'!D24) -> 0.03 | D11: ='Fee schedule'!B15 -> 0.025 | E11: 0 | F11: 0.08 | G11: 0 | H11: 1
A12: Private Equity | B12: =N('Fund balance sheet'!C25) -> 0 | C12: =N('Fund balance sheet'!D25) -> 0.03 | D12: ='Fee schedule'!B16 -> 0.03 | E12: 0 | F12: 0.08 | G12: 0 | H12: 1
A13: Australian Fixed Income | B13: =N('Fund balance sheet'!C13) -> 0.15 | C13: =N('Fund balance sheet'!D13) -> 0.14 | D13: ='Fee schedule'!B10 -> 0.001 | E13: 0.12 | F13: 0.25 | G13: 0 | H13: 0
A14: World Fixed Income | B14: =N('Fund balance sheet'!C14) -> 0.08 | C14: =N('Fund balance sheet'!D14) -> 0.11 | D14: ='Fee schedule'!B11 -> 0.0015 | E14: 0.05 | F14: 0.2 | G14: 0 | H14: 0
A15: Cash | B15: =N('Fund balance sheet'!C15) -> 0.07 | C15: =N('Fund balance sheet'!D15) -> 0.03 | D15: ='Fee schedule'!B5 -> 0 | E15: 0.02 | F15: 0.1 | G15: 0 | H15: 0
A16: Total | B16: =SUM(B5:B15) -> 1 | C16: =SUM(C5:C15) -> 1
A18: Australian fixed income floor 12%: home-currency defensive anchor; keeps the bond split stable against resampling (Methods section 3).
A20: 2. Mandate and constraints
A21: Parameter | B21: Value | C21: Source
A22: Funds under management (A$m) | B22: ='Fund balance sheet'!B29 -> 3000 | C22: Fund balance sheet
A23: 5-year bond yield | B23: 0.04988 | C23: RBA F2, 22-Sep-26
A24: Target spread | B24: 0.04 | C24: Brief
A25: Required return (yield + spread) | B25: =B23+B24 -> 0.08988 | C25: Calc
A26: Australian cash rate | B26: 0.046 | C26: RBA, 29-Sep-26
A27: Tracking error limit | B27: 0.015 | C27: Brief
A28: 5-year loss probability limit | B28: 0.25 | C28: Brief
A29: Equity band (+/-) | B29: 0.1 | C29: Brief
A30: Benchmark equity weight | B30: =SUMPRODUCT(C5:C15,G5:G15) -> 0.52 | C30: Calc
A31: Equity minimum | B31: =B30-B29 -> 0.42 | C31: Calc
A32: Equity maximum | B32: =B30+B29 -> 0.62 | C32: Calc
A33: Illiquid maximum | B33: 0.3 | C33: Brief
A34: Cash minimum | B34: 0.02 | C34: Brief
A36: 3. Model settings
A37: Parameter | B37: Value | C37: Source
A38: Shrinkage intensity | B38: 0.35 | C38: Ledoit-Wolf (2004)
A39: Direct property smoothing | B39: 0.65 | C39: Lag-1 autocorrelation
A40: Private equity smoothing | B40: 0.24 | C40: Lag-1 autocorrelation
A41: Risk aversion (delta) | B41: 4 | C41: Black-Litterman
A42: Max confidence in building blocks | B42: 0.65 | C42: Judgement
A43: Min confidence in building blocks | B43: 0.2 | C43: Judgement
A44: Method dispersion at min confidence | B44: 0.04 | C44: Judgement
...

Sheet Forecast
A1: Forecast
A3: 1. Summary
A5: Asset class | B5: Building-block composite (gross, arithmetic) | C5: Equilibrium prior | D5: Confidence | E5: Gross forecast | F5: Fee | G5: Net forecast | H5: Volatility | I5: View dispersion
A6: Australian Equities | B6: =G139 -> 0.078008816 | C6: =Inputs!$B$23+Inputs!$B$41*SUMPRODUCT(MMULT(Risk!$B$41:$L$41,Inputs!$C$5:$C$15)) -> 0.085434421 | D6: =Inputs!$B$42-(Inputs!$B$42-Inputs!$B$43)*MIN(1,I6/Inputs!$B$44) -> 0.4072028 | E6: =IF(Inputs!$B$46=1,AVERAGE((D6*B6+(1-D6)*C6),(D7*B7+(1-D7)*C7)),(D6*B6+(1-D6)*C6)) -> 0.078798125 | F6: =Inputs!D5 -> 0.001 | G6: =E6-F6 -> 0.077798125 | H6: =Risk!M41 -> 0.15381532 | I6: =I139 -> 0.021581973
A7: World Equities | B7: =G140 -> 0.069574729 | C7: =Inputs!$B$23+Inputs!$B$41*SUMPRODUCT(MMULT(Risk!$B$42:$L$42,Inputs!$C$5:$C$15)) -> 0.077973432 | D7: =Inputs!$B$42-(Inputs!$B$42-Inputs!$B$43)*MIN(1,I7/Inputs!$B$44) -> 0.33194119 | E7: =IF(Inputs!$B$46=1,AVERAGE((D6*B6+(1-D6)*C6),(D7*B7+(1-D7)*C7)),(D7*B7+(1-D7)*C7)) -> 0.078798125 | F7: =Inputs!D6 -> 0.0015 | G7: =E7-F7 -> 0.077298125 | H7: =Risk!M42 -> 0.12748315 | I7: =I140 -> 0.028271894
A8: Emerging Markets | B8: =G141 -> 0.079179468 | C8: =Inputs!$B$23+Inputs!$B$41*SUMPRODUCT(MMULT(Risk!$B$43:$L$43,Inputs!$C$5:$C$15)) -> 0.066679499 | D8: =Inputs!$B$42-(Inputs!$B$42-Inputs!$B$43)*MIN(1,I8/Inputs!$B$44) -> 0.48125 | E8: =(D8*B8+(1-D8)*C8) -> 0.072695109 | F8: =Inputs!D7 -> 0.002 | G8: =E8-F8 -> 0.070695109 | H8: =Risk!M43 -> 0.1049906 | I8: =I141 -> 0.015
A9: Listed Property | B9: =G142 -> 0.082782899 | C9: =Inputs!$B$23+Inputs!$B$41*SUMPRODUCT(MMULT(Risk!$B$44:$L$44,Inputs!$C$5:$C$15)) -> 0.07862403 | D9: =Inputs!$B$42-(Inputs!$B$42-Inputs!$B$43)*MIN(1,I9/Inputs!$B$44) -> 0.48125 | E9: =(D9*B9+(1-D9)*C9) -> 0.080625486 | F9: =Inputs!D8 -> 0.0015 | G9: =E9-F9 -> 0.079125486 | H9: =Risk!M44 -> 0.16766255 | I9: =I142 -> 0.015
A10: Commodities | B10: =G143 -> 0.086478574 | C10: =Inputs!$B$23+Inputs!$B$41*SUMPRODUCT(MMULT(Risk!$B$45:$L$45,Inputs!$C$5:$C$15)) -> 0.066007581 | D10: =Inputs!$B$42-(Inputs!$B$42-Inputs!$B$43)*MIN(1,I10/Inputs!$B$44) -> 0.3125 | E10: =(D10*B10+(1-D10)*C10) -> 0.072404767 | F10: =Inputs!D9 -> 0.0025 | G10: =E10-F10 -> 0.069904767 | H10: =Risk!M45 -> 0.24588035 | I10: =I143 -> 0.03
A11: Direct Property | B11: =G144 -> 0.054080974 | C11: =Inputs!$B$23+Inputs!$B$41*SUMPRODUCT(MMULT(Risk!$B$46:$L$46,Inputs!$C$5:$C$15)) -> 0.057809544 | D11: =Inputs!$B$42-(Inputs!$B$42-Inputs!$B$43)*MIN(1,I11/Inputs!$B$44) -> 0.425 | E11: =(D11*B11+(1-D11)*C11) -> 0.056224902 | F11: =Inputs!D10 -> 0.012 | G11: =E11-F11 -> 0.044224902 | H11: =Risk!M46 -> 0.095333549 | I11: =I144 -> 0.02
A12: Hedge Funds | B12: =G145 -> 0.079280702 | C12: =Inputs!$B$23+Inputs!$B$41*SUMPRODUCT(MMULT(Risk!$B$47:$L$47,Inputs!$C$5:$C$15)) -> 0.049701287 | D12: =Inputs!$B$42-(Inputs!$B$42-Inputs!$B$43)*MIN(1,I12/Inputs!$B$44) -> 0.425 | E12: =(D12*B12+(1-D12)*C12) -> 0.062272538 | F12: =Inputs!D11 -> 0.025 | G12: =E12-F12 -> 0.037272538 | H12: =Risk!M47 -> 0.071939397 | I12: =I145 -> 0.02
A13: Private Equity | B13: =G146 -> 0.11254628 | C13: =Inputs!$B$23+Inputs!$B$41*SUMPRODUCT(MMULT(Risk!$B$48:$L$48,Inputs!$C$5:$C$15)) -> 0.067396811 | D13: =Inputs!$B$42-(Inputs!$B$42-Inputs!$B$43)*MIN(1,I13/Inputs!$B$44) -> 0.3125 | E13: =(D13*B13+(1-D13)*C13) -> 0.081506021 | F13: =Inputs!D12 -> 0.03 | G13: =E13-F13 -> 0.051506021 | H13: =Risk!M48 -> 0.12724606 | I13: =I146 -> 0.03
A14: Australian Fixed Income | B14: =G147 -> 0.051402658 | C14: =Inputs!$B$23+Inputs!$B$41*SUMPRODUCT(MMULT(Risk!$B$49:$L$49,Inputs!$C$5:$C$15)) -> 0.050887359 | D14: =Inputs!$B$42-(Inputs!$B$42-Inputs!$B$43)*MIN(1,I14/Inputs!$B$44) -> 0.61625 | E14: =(D14*B14+(1-D14)*C14) -> 0.051204912 | F14: =Inputs!D13 -> 0.001 | G14: =E14-F14 -> 0.050204912 | H14: =Risk!M49 -> 0.042489011 | I14: =I147 -> 0.003
A15: World Fixed Income | B15: =G148 -> 0.057193023 | C15: =Inputs!$B$23+Inputs!$B$41*SUMPRODUCT(MMULT(Risk!$B$50:$L$50,Inputs!$C$5:$C$15)) -> 0.051289318 | D15: =Inputs!$B$42-(Inputs!$B$42-Inputs!$B$43)*MIN(1,I15/Inputs!$B$44) -> 0.59375 | E15: =(D15*B15+(1-D15)*C15) -> 0.054794643 | F15: =Inputs!D14 -> 0.0015 | G15: =E15-F15 -> 0.053294643 | H15: =Risk!M50 -> 0.040530808 | I15: =I148 -> 0.005
A16: Cash | B16: =G149 -> 0.046488137 | C16: =Inputs!$B$23+Inputs!$B$41*SUMPRODUCT(MMULT(Risk!$B$51:$L$51,Inputs!$C$5:$C$15)) -> 0.049641723 | D16: =Inputs!$B$42-(Inputs!$B$42-Inputs!$B$43)*MIN(1,I16/Inputs!$B$44) -> 0.61625 | E16: =(D16*B16+(1-D16)*C16) -> 0.047698326 | F16: =Inputs!D15 -> 0 | G16: =E16-F16 -> 0.047698326 | H16: =Risk!M51 -> 0.0098119767 | I16: =I149 -> 0.003
A18: Best single-asset forecast (compound) | G18: =MAX(M139:M149) -> 0.069172149
A19: Return target (bond yield + 4%) | G19: =Inputs!$B$25 -> 0.08988
A20: Target reachable? | G20: =IF(G18>=G19,"YES","NO") -> NO
A23: 2. Historical returns (adjusted quarterly data)
A24: Asset class | B24: 20-year CAGR | C24: 10-year CAGR | D24: 5-year CAGR | E24: Excess vs cash, 20y | F24: Excess vs cash, 10y | G24: Excess vs cash, 5y
A25: Australian Equities | B25: =EXP(SUMPRODUCT(LN(1+'Quarterly returns'!N$6:N$85))*4/80)-1 -> 0.06950125 | C25: =EXP(SUMPRODUCT(LN(1+'Quarterly returns'!N$46:N$85))*4/40)-1 -> 0.094599768 | D25: =EXP(SUMPRODUCT(LN(1+'Quarterly returns'!N$66:N$85))*4/20)-1 -> 0.0836422 | E25: =B25-B$35 -> 0.0364421 | F25: =C25-C$35 -> 0.072734217 | G25: =D25-D$35 -> 0.054730416
A26: World Equities | B26: =EXP(SUMPRODUCT(LN(1+'Quarterly returns'!O$6:O$85))*4/80)-1 -> 0.088450813 | C26: =EXP(SUMPRODUCT(LN(1+'Quarterly returns'!O$46:O$85))*4/40)-1 -> 0.14009824 | D26: =EXP(SUMPRODUCT(LN(1+'Quarterly returns'!O$66:O$85))*4/20)-1 -> 0.13819307 | E26: =B26-B$35 -> 0.055391663 | F26: =C26-C$35 -> 0.11823269 | G26: =D26-D$35 -> 0.10928129
A27: Emerging Markets | B27: =EXP(SUMPRODUCT(LN(1+'Quarterly returns'!P$6:P$85))*4/80)-1 -> 0.079988928 | C27: =EXP(SUMPRODUCT(LN(1+'Quarterly returns'!P$46:P$85))*4/40)-1 -> 0.11222714 | D27: =EXP(SUMPRODUCT(LN(1+'Quarterly returns'!P$66:P$85))*4/20)-1 -> 0.089739489 | E27: =B27-B$35 -> 0.046929778 | F27: =C27-C$35 -> 0.090361593 | G27: =D27-D$35 -> 0.060827705
A28: Listed Property | B28: =EXP(SUMPRODUCT(LN(1+'Quarterly returns'!Q$6:Q$85))*4/80)-1 -> 0.053753446 | C28: =EXP(SUMPRODUCT(LN(1+'Quarterly returns'!Q$46:Q$85))*4/40)-1 -> 0.059762085 | D28: =EXP(SUMPRODUCT(LN(1+'Quarterly returns'!Q$66:Q$85))*4/20)-1 -> 0.070428794 | E28: =B28-B$35 -> 0.020694296 | F28: =C28-C$35 -> 0.037896534 | G28: =D28-D$35 -> 0.04151701
A29: Commodities | B29: =EXP(SUMPRODUCT(LN(1+'Quarterly returns'!R$6:R$85))*4/80)-1 -> -0.0067382599 | C29: =EXP(SUMPRODUCT(LN(1+'Quarterly returns'!R$46:R$85))*4/40)-1 -> 0.1127272 | D29: =EXP(SUMPRODUCT(LN(1+'Quarterly returns'!R$66:R$85))*4/20)-1 -> 0.22123504 | E29: =B29-B$35 -> -0.039797409 | F29: =C29-C$35 -> 0.090861648 | G29: =D29-D$35 -> 0.19232325
A30: Direct Property | B30: =EXP(SUMPRODUCT(LN(1+'Quarterly returns'!S$6:S$85))*4/80)-1 -> 0.060608487 | C30: =EXP(SUMPRODUCT(LN(1+'Quarterly returns'!S$46:S$85))*4/40)-1 -> 0.056636213 | D30: =EXP(SUMPRODUCT(LN(1+'Quarterly returns'!S$66:S$85))*4/20)-1 -> 0.046465511 | E30: =B30-B$35 -> 0.027549338 | F30: =C30-C$35 -> 0.034770662 | G30: =D30-D$35 -> 0.017553727
A31: Hedge Funds | B31: =EXP(SUMPRODUCT(LN(1+'Quarterly returns'!T$6:T$85))*4/80)-1 -> 0.076551345 | C31: =EXP(SUMPRODUCT(LN(1+'Quarterly returns'!T$46:T$85))*4/40)-1 -> 0.075066369 | D31: =EXP(SUMPRODUCT(LN(1+'Quarterly returns'!T$66:T$85))*4/20)-1 -> 0.083698848 | E31: =B31-B$35 -> 0.043492196 | F31: =C31-C$35 -> 0.053200818 | G31: =D31-D$35 -> 0.054787063
A32: Private Equity | B32: =EXP(SUMPRODUCT(LN(1+'Quarterly returns'!U$6:U$85))*4/80)-1 -> 0.1068722 | C32: =EXP(SUMPRODUCT(LN(1+'Quarterly returns'!U$46:U$85))*4/40)-1 -> 0.10920514 | D32: =EXP(SUMPRODUCT(LN(1+'Quarterly returns'!U$66:U$85))*4/20)-1 -> 0.10226788 | E32: =B32-B$35 -> 0.073813048 | F32: =C32-C$35 -> 0.08733959 | G32: =D32-D$35 -> 0.073356092
A33: Australian Fixed Income | B33: =EXP(SUMPRODUCT(LN(1+'Quarterly returns'!V$6:V$85))*4/80)-1 -> 0.039606305 | C33: =EXP(SUMPRODUCT(LN(1+'Quarterly returns'!V$46:V$85))*4/40)-1 -> 0.016560819 | D33: =EXP(SUMPRODUCT(LN(1+'Quarterly returns'!V$66:V$85))*4/20)-1 -> -0.0008978244 | E33: =B33-B$35 -> 0.0065471554 | F33: =C33-C$35 -> -0.0053047319 | G33: =D33-D$35 -> -0.029809609
A34: World Fixed Income | B34: =EXP(SUMPRODUCT(LN(1+'Quarterly returns'!W$6:W$85))*4/80)-1 -> 0.043020943 | C34: =EXP(SUMPRODUCT(LN(1+'Quarterly returns'!W$46:W$85))*4/40)-1 -> 0.0093981374 | D34: =EXP(SUMPRODUCT(LN(1+'Quarterly returns'!W$66:W$85))*4/20)-1 -> -0.011384459 | E34: =B34-B$35 -> 0.0099617934 | F34: =C34-C$35 -> -0.012467414 | G34: =D34-D$35 -> -0.040296243
A35: Cash | B35: =EXP(SUMPRODUCT(LN(1+'Quarterly returns'!X$6:X$85))*4/80)-1 -> 0.033059149 | C35: =EXP(SUMPRODUCT(LN(1+'Quarterly returns'!X$46:X$85))*4/40)-1 -> 0.021865551 | D35: =EXP(SUMPRODUCT(LN(1+'Quarterly returns'!X$66:X$85))*4/20)-1 -> 0.028911784 | E35: =B35-B$35 -> 0 | F35: =C35-C$35 -> 0 | G35: =D35-D$35 -> 0
A38: 3. Implied equity returns
A39: Item | B39: Australian equities | C39: World equities | D39: Source
A40: As at | B40: 46265 | C40: 46265
A41: Dividend yield (trailing) | B41: 0.0343 | C41: 0.015 | D41: Market data
A42: P/E (trailing) | B42: 20.39 | C42: 23.2
A43: P/E (forward) | B43: 18.82 | C43: 18.55
A44: Expected inflation | B44: =$B$58 -> 0.0275 | C44: =$B$59 -> 0.025 | D44: Section 4
A45: Real growth | B45: =$B$65 -> 0.02 | C45: =$B$70 -> 0.018 | D45: Section 4
A46: Forward dividend yield | B46: =B41*B42/B43 -> 0.037161371 | C46: =C41*C42/C43 -> 0.018760108
A47: Nominal growth | B47: =B44+B45 -> 0.0475 | C47: =C44+C45 -> 0.043
...

Sheet Risk
A1: Risk
A3: 1. Sample covariance (annualised, adjusted quarterly returns)
A4: Asset class | B4: Australian Equities | C4: World Equities | D4: Emerging Markets | E4: Listed Property | F4: Commodities | G4: Direct Property | H4: Hedge Funds | I4: Private Equity | J4: Australian Fixed Income | K4: World Fixed Income | L4: Cash | M4: Sample vol
A5: Australian Equities | B5: =_xlfn.COVARIANCE.S('Quarterly returns'!$N$6:$N$85,'Quarterly returns'!$N$6:$N$85)*4 -> 0.023659152 | C5: =_xlfn.COVARIANCE.S('Quarterly returns'!$N$6:$N$85,'Quarterly returns'!$O$6:$O$85)*4 -> 0.010201113 | D5: =_xlfn.COVARIANCE.S('Quarterly returns'!$N$6:$N$85,'Quarterly returns'!$P$6:$P$85)*4 -> 0.0093962404 | E5: =_xlfn.COVARIANCE.S('Quarterly returns'!$N$6:$N$85,'Quarterly returns'!$Q$6:$Q$85)*4 -> 0.011218765 | F5: =_xlfn.COVARIANCE.S('Quarterly returns'!$N$6:$N$85,'Quarterly returns'!$R$6:$R$85)*4 -> 0.0093552336 | G5: =_xlfn.COVARIANCE.S('Quarterly returns'!$N$6:$N$85,'Quarterly returns'!$S$6:$S$85)*4 -> 0.003164105 | H5: =_xlfn.COVARIANCE.S('Quarterly returns'!$N$6:$N$85,'Quarterly returns'!$T$6:$T$85)*4 -> -0.0020963989 | I5: =_xlfn.COVARIANCE.S('Quarterly returns'!$N$6:$N$85,'Quarterly returns'!$U$6:$U$85)*4 -> 0.010511054 | J5: =_xlfn.COVARIANCE.S('Quarterly returns'!$N$6:$N$85,'Quarterly returns'!$V$6:$V$85)*4 -> -0.0010678114 | K5: =_xlfn.COVARIANCE.S('Quarterly returns'!$N$6:$N$85,'Quarterly returns'!$W$6:$W$85)*4 -> 0.00017412555 | L5: =_xlfn.COVARIANCE.S('Quarterly returns'!$N$6:$N$85,'Quarterly returns'!$X$6:$X$85)*4 -> -0.00028218901 | M5: =SQRT(B5) -> 0.15381532
A6: World Equities | B6: =_xlfn.COVARIANCE.S('Quarterly returns'!$O$6:$O$85,'Quarterly returns'!$N$6:$N$85)*4 -> 0.010201113 | C6: =_xlfn.COVARIANCE.S('Quarterly returns'!$O$6:$O$85,'Quarterly returns'!$O$6:$O$85)*4 -> 0.016251953 | D6: =_xlfn.COVARIANCE.S('Quarterly returns'!$O$6:$O$85,'Quarterly returns'!$P$6:$P$85)*4 -> 0.0091897284 | E6: =_xlfn.COVARIANCE.S('Quarterly returns'!$O$6:$O$85,'Quarterly returns'!$Q$6:$Q$85)*4 -> 0.014691055 | F6: =_xlfn.COVARIANCE.S('Quarterly returns'!$O$6:$O$85,'Quarterly returns'!$R$6:$R$85)*4 -> 0.0060217523 | G6: =_xlfn.COVARIANCE.S('Quarterly returns'!$O$6:$O$85,'Quarterly returns'!$S$6:$S$85)*4 -> 0.0034416564 | H6: =_xlfn.COVARIANCE.S('Quarterly returns'!$O$6:$O$85,'Quarterly returns'!$T$6:$T$85)*4 -> -0.00025929381 | I6: =_xlfn.COVARIANCE.S('Quarterly returns'!$O$6:$O$85,'Quarterly returns'!$U$6:$U$85)*4 -> 0.0074619821 | J6: =_xlfn.COVARIANCE.S('Quarterly returns'!$O$6:$O$85,'Quarterly returns'!$V$6:$V$85)*4 -> -0.00021924073 | K6: =_xlfn.COVARIANCE.S('Quarterly returns'!$O$6:$O$85,'Quarterly returns'!$W$6:$W$85)*4 -> -0.00063739192 | L6: =_xlfn.COVARIANCE.S('Quarterly returns'!$O$6:$O$85,'Quarterly returns'!$X$6:$X$85)*4 -> -0.00033337705 | M6: =SQRT(C6) -> 0.12748315
A7: Emerging Markets | B7: =_xlfn.COVARIANCE.S('Quarterly returns'!$P$6:$P$85,'Quarterly returns'!$N$6:$N$85)*4 -> 0.0093962404 | C7: =_xlfn.COVARIANCE.S('Quarterly returns'!$P$6:$P$85,'Quarterly returns'!$O$6:$O$85)*4 -> 0.0091897284 | D7: =_xlfn.COVARIANCE.S('Quarterly returns'!$P$6:$P$85,'Quarterly returns'!$P$6:$P$85)*4 -> 0.011023027 | E7: =_xlfn.COVARIANCE.S('Quarterly returns'!$P$6:$P$85,'Quarterly returns'!$Q$6:$Q$85)*4 -> 0.0067816259 | F7: =_xlfn.COVARIANCE.S('Quarterly returns'!$P$6:$P$85,'Quarterly returns'!$R$6:$R$85)*4 -> 0.0051228004 | G7: =_xlfn.COVARIANCE.S('Quarterly returns'!$P$6:$P$85,'Quarterly returns'!$S$6:$S$85)*4 -> 0.0041754167 | H7: =_xlfn.COVARIANCE.S('Quarterly returns'!$P$6:$P$85,'Quarterly returns'!$T$6:$T$85)*4 -> -6.2837013e-05 | I7: =_xlfn.COVARIANCE.S('Quarterly returns'!$P$6:$P$85,'Quarterly returns'!$U$6:$U$85)*4 -> 0.0040455748 | J7: =_xlfn.COVARIANCE.S('Quarterly returns'!$P$6:$P$85,'Quarterly returns'!$V$6:$V$85)*4 -> -0.00055660691 | K7: =_xlfn.COVARIANCE.S('Quarterly returns'!$P$6:$P$85,'Quarterly returns'!$W$6:$W$85)*4 -> -0.00032363921 | L7: =_xlfn.COVARIANCE.S('Quarterly returns'!$P$6:$P$85,'Quarterly returns'!$X$6:$X$85)*4 -> -0.00018014153 | M7: =SQRT(D7) -> 0.1049906
A8: Listed Property | B8: =_xlfn.COVARIANCE.S('Quarterly returns'!$Q$6:$Q$85,'Quarterly returns'!$N$6:$N$85)*4 -> 0.011218765 | C8: =_xlfn.COVARIANCE.S('Quarterly returns'!$Q$6:$Q$85,'Quarterly returns'!$O$6:$O$85)*4 -> 0.014691055 | D8: =_xlfn.COVARIANCE.S('Quarterly returns'!$Q$6:$Q$85,'Quarterly returns'!$P$6:$P$85)*4 -> 0.0067816259 | E8: =_xlfn.COVARIANCE.S('Quarterly returns'!$Q$6:$Q$85,'Quarterly returns'!$Q$6:$Q$85)*4 -> 0.028110729 | F8: =_xlfn.COVARIANCE.S('Quarterly returns'!$Q$6:$Q$85,'Quarterly returns'!$R$6:$R$85)*4 -> 0.0032896337 | G8: =_xlfn.COVARIANCE.S('Quarterly returns'!$Q$6:$Q$85,'Quarterly returns'!$S$6:$S$85)*4 -> 0.0016672375 | H8: =_xlfn.COVARIANCE.S('Quarterly returns'!$Q$6:$Q$85,'Quarterly returns'!$T$6:$T$85)*4 -> -0.0019657819 | I8: =_xlfn.COVARIANCE.S('Quarterly returns'!$Q$6:$Q$85,'Quarterly returns'!$U$6:$U$85)*4 -> 0.007622374 | J8: =_xlfn.COVARIANCE.S('Quarterly returns'!$Q$6:$Q$85,'Quarterly returns'!$V$6:$V$85)*4 -> 0.0011424276 | K8: =_xlfn.COVARIANCE.S('Quarterly returns'!$Q$6:$Q$85,'Quarterly returns'!$W$6:$W$85)*4 -> 0.0011450282 | L8: =_xlfn.COVARIANCE.S('Quarterly returns'!$Q$6:$Q$85,'Quarterly returns'!$X$6:$X$85)*4 -> -0.00029733142 | M8: =SQRT(E8) -> 0.16766255
A9: Commodities | B9: =_xlfn.COVARIANCE.S('Quarterly returns'!$R$6:$R$85,'Quarterly returns'!$N$6:$N$85)*4 -> 0.0093552336 | C9: =_xlfn.COVARIANCE.S('Quarterly returns'!$R$6:$R$85,'Quarterly returns'!$O$6:$O$85)*4 -> 0.0060217523 | D9: =_xlfn.COVARIANCE.S('Quarterly returns'!$R$6:$R$85,'Quarterly returns'!$P$6:$P$85)*4 -> 0.0051228004 | E9: =_xlfn.COVARIANCE.S('Quarterly returns'!$R$6:$R$85,'Quarterly returns'!$Q$6:$Q$85)*4 -> 0.0032896337 | F9: =_xlfn.COVARIANCE.S('Quarterly returns'!$R$6:$R$85,'Quarterly returns'!$R$6:$R$85)*4 -> 0.060457147 | G9: =_xlfn.COVARIANCE.S('Quarterly returns'!$R$6:$R$85,'Quarterly returns'!$S$6:$S$85)*4 -> 0.0048364771 | H9: =_xlfn.COVARIANCE.S('Quarterly returns'!$R$6:$R$85,'Quarterly returns'!$T$6:$T$85)*4 -> -0.0029536532 | I9: =_xlfn.COVARIANCE.S('Quarterly returns'!$R$6:$R$85,'Quarterly returns'!$U$6:$U$85)*4 -> -0.00028250152 | J9: =_xlfn.COVARIANCE.S('Quarterly returns'!$R$6:$R$85,'Quarterly returns'!$V$6:$V$85)*4 -> -0.0054720198 | K9: =_xlfn.COVARIANCE.S('Quarterly returns'!$R$6:$R$85,'Quarterly returns'!$W$6:$W$85)*4 -> -0.0054841287 | L9: =_xlfn.COVARIANCE.S('Quarterly returns'!$R$6:$R$85,'Quarterly returns'!$X$6:$X$85)*4 -> -0.0003053015 | M9: =SQRT(F9) -> 0.24588035
A10: Direct Property | B10: =_xlfn.COVARIANCE.S('Quarterly returns'!$S$6:$S$85,'Quarterly returns'!$N$6:$N$85)*4 -> 0.003164105 | C10: =_xlfn.COVARIANCE.S('Quarterly returns'!$S$6:$S$85,'Quarterly returns'!$O$6:$O$85)*4 -> 0.0034416564 | D10: =_xlfn.COVARIANCE.S('Quarterly returns'!$S$6:$S$85,'Quarterly returns'!$P$6:$P$85)*4 -> 0.0041754167 | E10: =_xlfn.COVARIANCE.S('Quarterly returns'!$S$6:$S$85,'Quarterly returns'!$Q$6:$Q$85)*4 -> 0.0016672375 | F10: =_xlfn.COVARIANCE.S('Quarterly returns'!$S$6:$S$85,'Quarterly returns'!$R$6:$R$85)*4 -> 0.0048364771 | G10: =_xlfn.COVARIANCE.S('Quarterly returns'!$S$6:$S$85,'Quarterly returns'!$S$6:$S$85)*4 -> 0.0090884856 | H10: =_xlfn.COVARIANCE.S('Quarterly returns'!$S$6:$S$85,'Quarterly returns'!$T$6:$T$85)*4 -> 0.0004080026 | I10: =_xlfn.COVARIANCE.S('Quarterly returns'!$S$6:$S$85,'Quarterly returns'!$U$6:$U$85)*4 -> 0.0023270627 | J10: =_xlfn.COVARIANCE.S('Quarterly returns'!$S$6:$S$85,'Quarterly returns'!$V$6:$V$85)*4 -> -0.0011143499 | K10: =_xlfn.COVARIANCE.S('Quarterly returns'!$S$6:$S$85,'Quarterly returns'!$W$6:$W$85)*4 -> -0.00067265871 | L10: =_xlfn.COVARIANCE.S('Quarterly returns'!$S$6:$S$85,'Quarterly returns'!$X$6:$X$85)*4 -> -0.00013132648 | M10: =SQRT(G10) -> 0.095333549
A11: Hedge Funds | B11: =_xlfn.COVARIANCE.S('Quarterly returns'!$T$6:$T$85,'Quarterly returns'!$N$6:$N$85)*4 -> -0.0020963989 | C11: =_xlfn.COVARIANCE.S('Quarterly returns'!$T$6:$T$85,'Quarterly returns'!$O$6:$O$85)*4 -> -0.00025929381 | D11: =_xlfn.COVARIANCE.S('Quarterly returns'!$T$6:$T$85,'Quarterly returns'!$P$6:$P$85)*4 -> -6.2837013e-05 | E11: =_xlfn.COVARIANCE.S('Quarterly returns'!$T$6:$T$85,'Quarterly returns'!$Q$6:$Q$85)*4 -> -0.0019657819 | F11: =_xlfn.COVARIANCE.S('Quarterly returns'!$T$6:$T$85,'Quarterly returns'!$R$6:$R$85)*4 -> -0.0029536532 | G11: =_xlfn.COVARIANCE.S('Quarterly returns'!$T$6:$T$85,'Quarterly returns'!$S$6:$S$85)*4 -> 0.0004080026 | H11: =_xlfn.COVARIANCE.S('Quarterly returns'!$T$6:$T$85,'Quarterly returns'!$T$6:$T$85)*4 -> 0.0051752768 | I11: =_xlfn.COVARIANCE.S('Quarterly returns'!$T$6:$T$85,'Quarterly returns'!$U$6:$U$85)*4 -> -0.00063140198 | J11: =_xlfn.COVARIANCE.S('Quarterly returns'!$T$6:$T$85,'Quarterly returns'!$V$6:$V$85)*4 -> 0.00035220021 | K11: =_xlfn.COVARIANCE.S('Quarterly returns'!$T$6:$T$85,'Quarterly returns'!$W$6:$W$85)*4 -> 5.021398e-06 | L11: =_xlfn.COVARIANCE.S('Quarterly returns'!$T$6:$T$85,'Quarterly returns'!$X$6:$X$85)*4 -> 0.00010340346 | M11: =SQRT(H11) -> 0.071939397
A12: Private Equity | B12: =_xlfn.COVARIANCE.S('Quarterly returns'!$U$6:$U$85,'Quarterly returns'!$N$6:$N$85)*4 -> 0.010511054 | C12: =_xlfn.COVARIANCE.S('Quarterly returns'!$U$6:$U$85,'Quarterly returns'!$O$6:$O$85)*4 -> 0.0074619821 | D12: =_xlfn.COVARIANCE.S('Quarterly returns'!$U$6:$U$85,'Quarterly returns'!$P$6:$P$85)*4 -> 0.0040455748 | E12: =_xlfn.COVARIANCE.S('Quarterly returns'!$U$6:$U$85,'Quarterly returns'!$Q$6:$Q$85)*4 -> 0.007622374 | F12: =_xlfn.COVARIANCE.S('Quarterly returns'!$U$6:$U$85,'Quarterly returns'!$R$6:$R$85)*4 -> -0.00028250152 | G12: =_xlfn.COVARIANCE.S('Quarterly returns'!$U$6:$U$85,'Quarterly returns'!$S$6:$S$85)*4 -> 0.0023270627 | H12: =_xlfn.COVARIANCE.S('Quarterly returns'!$U$6:$U$85,'Quarterly returns'!$T$6:$T$85)*4 -> -0.00063140198 | I12: =_xlfn.COVARIANCE.S('Quarterly returns'!$U$6:$U$85,'Quarterly returns'!$U$6:$U$85)*4 -> 0.01619156 | J12: =_xlfn.COVARIANCE.S('Quarterly returns'!$U$6:$U$85,'Quarterly returns'!$V$6:$V$85)*4 -> 0.00032821521 | K12: =_xlfn.COVARIANCE.S('Quarterly returns'!$U$6:$U$85,'Quarterly returns'!$W$6:$W$85)*4 -> 0.00042088405 | L12: =_xlfn.COVARIANCE.S('Quarterly returns'!$U$6:$U$85,'Quarterly returns'!$X$6:$X$85)*4 -> -0.00013855702 | M12: =SQRT(I12) -> 0.12724606
A13: Australian Fixed Income | B13: =_xlfn.COVARIANCE.S('Quarterly returns'!$V$6:$V$85,'Quarterly returns'!$N$6:$N$85)*4 -> -0.0010678114 | C13: =_xlfn.COVARIANCE.S('Quarterly returns'!$V$6:$V$85,'Quarterly returns'!$O$6:$O$85)*4 -> -0.00021924073 | D13: =_xlfn.COVARIANCE.S('Quarterly returns'!$V$6:$V$85,'Quarterly returns'!$P$6:$P$85)*4 -> -0.00055660691 | E13: =_xlfn.COVARIANCE.S('Quarterly returns'!$V$6:$V$85,'Quarterly returns'!$Q$6:$Q$85)*4 -> 0.0011424276 | F13: =_xlfn.COVARIANCE.S('Quarterly returns'!$V$6:$V$85,'Quarterly returns'!$R$6:$R$85)*4 -> -0.0054720198 | G13: =_xlfn.COVARIANCE.S('Quarterly returns'!$V$6:$V$85,'Quarterly returns'!$S$6:$S$85)*4 -> -0.0011143499 | H13: =_xlfn.COVARIANCE.S('Quarterly returns'!$V$6:$V$85,'Quarterly returns'!$T$6:$T$85)*4 -> 0.00035220021 | I13: =_xlfn.COVARIANCE.S('Quarterly returns'!$V$6:$V$85,'Quarterly returns'!$U$6:$U$85)*4 -> 0.00032821521 | J13: =_xlfn.COVARIANCE.S('Quarterly returns'!$V$6:$V$85,'Quarterly returns'!$V$6:$V$85)*4 -> 0.0018053161 | K13: =_xlfn.COVARIANCE.S('Quarterly returns'!$V$6:$V$85,'Quarterly returns'!$W$6:$W$85)*4 -> 0.0014020089 | L13: =_xlfn.COVARIANCE.S('Quarterly returns'!$V$6:$V$85,'Quarterly returns'!$X$6:$X$85)*4 -> 0.00014748733 | M13: =SQRT(J13) -> 0.042489011
A14: World Fixed Income | B14: =_xlfn.COVARIANCE.S('Quarterly returns'!$W$6:$W$85,'Quarterly returns'!$N$6:$N$85)*4 -> 0.00017412555 | C14: =_xlfn.COVARIANCE.S('Quarterly returns'!$W$6:$W$85,'Quarterly returns'!$O$6:$O$85)*4 -> -0.00063739192 | D14: =_xlfn.COVARIANCE.S('Quarterly returns'!$W$6:$W$85,'Quarterly returns'!$P$6:$P$85)*4 -> -0.00032363921 | E14: =_xlfn.COVARIANCE.S('Quarterly returns'!$W$6:$W$85,'Quarterly returns'!$Q$6:$Q$85)*4 -> 0.0011450282 | F14: =_xlfn.COVARIANCE.S('Quarterly returns'!$W$6:$W$85,'Quarterly returns'!$R$6:$R$85)*4 -> -0.0054841287 | G14: =_xlfn.COVARIANCE.S('Quarterly returns'!$W$6:$W$85,'Quarterly returns'!$S$6:$S$85)*4 -> -0.00067265871 | H14: =_xlfn.COVARIANCE.S('Quarterly returns'!$W$6:$W$85,'Quarterly returns'!$T$6:$T$85)*4 -> 5.021398e-06 | I14: =_xlfn.COVARIANCE.S('Quarterly returns'!$W$6:$W$85,'Quarterly returns'!$U$6:$U$85)*4 -> 0.00042088405 | J14: =_xlfn.COVARIANCE.S('Quarterly returns'!$W$6:$W$85,'Quarterly returns'!$V$6:$V$85)*4 -> 0.0014020089 | K14: =_xlfn.COVARIANCE.S('Quarterly returns'!$W$6:$W$85,'Quarterly returns'!$W$6:$W$85)*4 -> 0.0016427464 | L14: =_xlfn.COVARIANCE.S('Quarterly returns'!$W$6:$W$85,'Quarterly returns'!$X$6:$X$85)*4 -> 0.00013721798 | M14: =SQRT(K14) -> 0.040530808
A15: Cash | B15: =_xlfn.COVARIANCE.S('Quarterly returns'!$X$6:$X$85,'Quarterly returns'!$N$6:$N$85)*4 -> -0.00028218901 | C15: =_xlfn.COVARIANCE.S('Quarterly returns'!$X$6:$X$85,'Quarterly returns'!$O$6:$O$85)*4 -> -0.00033337705 | D15: =_xlfn.COVARIANCE.S('Quarterly returns'!$X$6:$X$85,'Quarterly returns'!$P$6:$P$85)*4 -> -0.00018014153 | E15: =_xlfn.COVARIANCE.S('Quarterly returns'!$X$6:$X$85,'Quarterly returns'!$Q$6:$Q$85)*4 -> -0.00029733142 | F15: =_xlfn.COVARIANCE.S('Quarterly returns'!$X$6:$X$85,'Quarterly returns'!$R$6:$R$85)*4 -> -0.0003053015 | G15: =_xlfn.COVARIANCE.S('Quarterly returns'!$X$6:$X$85,'Quarterly returns'!$S$6:$S$85)*4 -> -0.00013132648 | H15: =_xlfn.COVARIANCE.S('Quarterly returns'!$X$6:$X$85,'Quarterly returns'!$T$6:$T$85)*4 -> 0.00010340346 | I15: =_xlfn.COVARIANCE.S('Quarterly returns'!$X$6:$X$85,'Quarterly returns'!$U$6:$U$85)*4 -> -0.00013855702 | J15: =_xlfn.COVARIANCE.S('Quarterly returns'!$X$6:$X$85,'Quarterly returns'!$V$6:$V$85)*4 -> 0.00014748733 | K15: =_xlfn.COVARIANCE.S('Quarterly returns'!$X$6:$X$85,'Quarterly returns'!$W$6:$W$85)*4 -> 0.00013721798 | L15: =_xlfn.COVARIANCE.S('Quarterly returns'!$X$6:$X$85,'Quarterly returns'!$X$6:$X$85)*4 -> 9.6274886e-05 | M15: =SQRT(L15) -> 0.0098119767
A18: 2. Correlation
A19: Asset class | B19: Australian Equities | C19: World Equities | D19: Emerging Markets | E19: Listed Property | F19: Commodities | G19: Direct Property | H19: Hedge Funds | I19: Private Equity | J19: Australian Fixed Income | K19: World Fixed Income | L19: Cash
A20: Australian Equities | B20: =B5/($M5*$M$5) -> 1 | C20: =C5/($M5*$M$6) -> 0.52022975 | D20: =D5/($M5*$M$7) -> 0.5818407 | E20: =E5/($M5*$M$8) -> 0.43502018 | F20: =F5/($M5*$M$9) -> 0.247361 | G20: =G5/($M5*$M$10) -> 0.2157772 | H20: =H5/($M5*$M$11) -> -0.18945564 | I20: =I5/($M5*$M$12) -> 0.53703467 | J20: =J5/($M5*$M$13) -> -0.16338731 | K20: =K5/($M5*$M$14) -> 0.027930433 | L20: =L5/($M5*$M$15) -> -0.1869752
A21: World Equities | B21: =B6/($M6*$M$5) -> 0.52022975 | C21: =C6/($M6*$M$6) -> 1 | D21: =D6/($M6*$M$7) -> 0.68659313 | E21: =E6/($M6*$M$8) -> 0.68732817 | F21: =F6/($M6*$M$9) -> 0.19210837 | G21: =G6/($M6*$M$10) -> 0.28318416 | H21: =H6/($M6*$M$11) -> -0.028273044 | I21: =I6/($M6*$M$12) -> 0.45999921 | J21: =J6/($M6*$M$13) -> -0.040475463 | K21: =K6/($M6*$M$14) -> -0.12335834 | L21: =L6/($M6*$M$15) -> -0.26651791
A22: Emerging Markets | B22: =B7/($M7*$M$5) -> 0.5818407 | C22: =C7/($M7*$M$6) -> 0.68659313 | D22: =D7/($M7*$M$7) -> 1 | E22: =E7/($M7*$M$8) -> 0.38525416 | F22: =F7/($M7*$M$9) -> 0.19844181 | G22: =G7/($M7*$M$10) -> 0.41716093 | H22: =H7/($M7*$M$11) -> -0.0083195206 | I22: =I7/($M7*$M$12) -> 0.30282063 | J22: =J7/($M7*$M$13) -> -0.12477326 | K22: =K7/($M7*$M$14) -> -0.076054592 | L22: =L7/($M7*$M$15) -> -0.17486662
A23: Listed Property | B23: =B8/($M8*$M$5) -> 0.43502018 | C23: =C8/($M8*$M$6) -> 0.68732817 | D23: =D8/($M8*$M$7) -> 0.38525416 | E23: =E8/($M8*$M$8) -> 1 | F23: =F8/($M8*$M$9) -> 0.079797201 | G23: =G8/($M8*$M$10) -> 0.10430753 | H23: =H8/($M8*$M$11) -> -0.16297931 | I23: =I8/($M8*$M$12) -> 0.35728095 | J23: =J8/($M8*$M$13) -> 0.16036736 | K23: =K8/($M8*$M$14) -> 0.16849804 | L23: =L8/($M8*$M$15) -> -0.18073749
A24: Commodities | B24: =B9/($M9*$M$5) -> 0.247361 | C24: =C9/($M9*$M$6) -> 0.19210837 | D24: =D9/($M9*$M$7) -> 0.19844181 | E24: =E9/($M9*$M$8) -> 0.079797201 | F24: =F9/($M9*$M$9) -> 1 | G24: =G9/($M9*$M$10) -> 0.20632865 | H24: =H9/($M9*$M$11) -> -0.1669817 | I24: =I9/($M9*$M$12) -> -0.0090292696 | J24: =J9/($M9*$M$13) -> -0.52377795 | K24: =K9/($M9*$M$14) -> -0.55029878 | L24: =L9/($M9*$M$15) -> -0.12654605
A25: Direct Property | B25: =B10/($M10*$M$5) -> 0.2157772 | C25: =C10/($M10*$M$6) -> 0.28318416 | D25: =D10/($M10*$M$7) -> 0.41716093 | E25: =E10/($M10*$M$8) -> 0.10430753 | F25: =F10/($M10*$M$9) -> 0.20632865 | G25: =G10/($M10*$M$10) -> 1 | H25: =H10/($M10*$M$11) -> 0.059490877 | I25: =I10/($M10*$M$12) -> 0.19183064 | J25: =J10/($M10*$M$13) -> -0.27510544 | K25: =K10/($M10*$M$14) -> -0.17408596 | L25: =L10/($M10*$M$15) -> -0.14039448
A26: Hedge Funds | B26: =B11/($M11*$M$5) -> -0.18945564 | C26: =C11/($M11*$M$6) -> -0.028273044 | D26: =D11/($M11*$M$7) -> -0.0083195206 | E26: =E11/($M11*$M$8) -> -0.16297931 | F26: =F11/($M11*$M$9) -> -0.1669817 | G26: =G11/($M11*$M$10) -> 0.059490877 | H26: =H11/($M11*$M$11) -> 1 | I26: =I11/($M11*$M$12) -> -0.068975492 | J26: =J11/($M11*$M$13) -> 0.11522486 | K26: =K11/($M11*$M$14) -> 0.0017221564 | L26: =L11/($M11*$M$15) -> 0.14649128
A27: Private Equity | B27: =B12/($M12*$M$5) -> 0.53703467 | C27: =C12/($M12*$M$6) -> 0.45999921 | D27: =D12/($M12*$M$7) -> 0.30282063 | E27: =E12/($M12*$M$8) -> 0.35728095 | F27: =F12/($M12*$M$9) -> -0.0090292696 | G27: =G12/($M12*$M$10) -> 0.19183064 | H27: =H12/($M12*$M$11) -> -0.068975492 | I27: =I12/($M12*$M$12) -> 1 | J27: =J12/($M12*$M$13) -> 0.060706856 | K27: =K12/($M12*$M$14) -> 0.081608025 | L27: =L12/($M12*$M$15) -> -0.11097565
A28: Australian Fixed Income | B28: =B13/($M13*$M$5) -> -0.16338731 | C28: =C13/($M13*$M$6) -> -0.040475463 | D28: =D13/($M13*$M$7) -> -0.12477326 | E28: =E13/($M13*$M$8) -> 0.16036736 | F28: =F13/($M13*$M$9) -> -0.52377795 | G28: =G13/($M13*$M$10) -> -0.27510544 | H28: =H13/($M13*$M$11) -> 0.11522486 | I28: =I13/($M13*$M$12) -> 0.060706856 | J28: =J13/($M13*$M$13) -> 1 | K28: =K13/($M13*$M$14) -> 0.81412085 | L28: =L13/($M13*$M$15) -> 0.35377048
A29: World Fixed Income | B29: =B14/($M14*$M$5) -> 0.027930433 | C29: =C14/($M14*$M$6) -> -0.12335834 | D29: =D14/($M14*$M$7) -> -0.076054592 | E29: =E14/($M14*$M$8) -> 0.16849804 | F29: =F14/($M14*$M$9) -> -0.55029878 | G29: =G14/($M14*$M$10) -> -0.17408596 | H29: =H14/($M14*$M$11) -> 0.0017221564 | I29: =I14/($M14*$M$12) -> 0.081608025 | J29: =J14/($M14*$M$13) -> 0.81412085 | K29: =K14/($M14*$M$14) -> 1 | L29: =L14/($M14*$M$15) -> 0.34503985
A30: Cash | B30: =B15/($M15*$M$5) -> -0.1869752 | C30: =C15/($M15*$M$6) -> -0.26651791 | D30: =D15/($M15*$M$7) -> -0.17486662 | E30: =E15/($M15*$M$8) -> -0.18073749 | F30: =F15/($M15*$M$9) -> -0.12654605 | G30: =G15/($M15*$M$10) -> -0.14039448 | H30: =H15/($M15*$M$11) -> 0.14649128 | I30: =I15/($M15*$M$12) -> -0.11097565 | J30: =J15/($M15*$M$13) -> 0.35377048 | K30: =K15/($M15*$M$14) -> 0.34503985 | L30: =L15/($M15*$M$15) -> 1
A32: Average correlation (target) | B32: =(SUM(B20:L30)-11)/110 -> 0.10095138
A38: 3. Shrunk covariance
A40: Asset class | B40: Australian Equities | C40: World Equities | D40: Emerging Markets | E40: Listed Property | F40: Commodities | G40: Direct Property | H40: Hedge Funds | I40: Private Equity | J40: Australian Fixed Income | K40: World Fixed Income | L40: Cash | M40: Shrunk vol
A41: Australian Equities | B41: =B5 -> 0.023659152 | C41: =(1-Inputs!$B$38)*C5+Inputs!$B$38*$B$32*$M5*$M$6 -> 0.0073235629 | D41: =(1-Inputs!$B$38)*D5+Inputs!$B$38*$B$32*$M5*$M$7 -> 0.0066781543 | E41: =(1-Inputs!$B$38)*E5+Inputs!$B$38*$B$32*$M5*$M$8 -> 0.0082034018 | F41: =(1-Inputs!$B$38)*F5+Inputs!$B$38*$B$32*$M5*$M$9 -> 0.007417201 | G41: =(1-Inputs!$B$38)*G5+Inputs!$B$38*$B$32*$M5*$M$10 -> 0.0025747826 | H41: =(1-Inputs!$B$38)*H5+Inputs!$B$38*$B$32*$M5*$M$11 -> -0.00097168636 | I41: =(1-Inputs!$B$38)*I5+Inputs!$B$38*$B$32*$M5*$M$12 -> 0.0075237358 | J41: =(1-Inputs!$B$38)*J5+Inputs!$B$38*$B$32*$M5*$M$13 -> -0.00046316007 | K41: =(1-Inputs!$B$38)*K5+Inputs!$B$38*$B$32*$M5*$M$14 -> 0.00033345657 | L41: =(1-Inputs!$B$38)*L5+Inputs!$B$38*$B$32*$M5*$M$15 -> -0.00013009718 | M41: =SQRT(B41) -> 0.15381532
A42: World Equities | B42: =(1-Inputs!$B$38)*B6+Inputs!$B$38*$B$32*$M6*$M$5 -> 0.0073235629 | C42: =C6 -> 0.016251953 | D42: =(1-Inputs!$B$38)*D6+Inputs!$B$38*$B$32*$M6*$M$7 -> 0.0064462389 | E42: =(1-Inputs!$B$38)*E6+Inputs!$B$38*$B$32*$M6*$M$8 -> 0.010304398 | F42: =(1-Inputs!$B$38)*F6+Inputs!$B$38*$B$32*$M6*$M$9 -> 0.0050216726 | G42: =(1-Inputs!$B$38)*G6+Inputs!$B$38*$B$32*$M6*$M$10 -> 0.0026664933 | H42: =(1-Inputs!$B$38)*H6+Inputs!$B$38*$B$32*$M6*$M$11 -> 0.00015549994 | I42: =(1-Inputs!$B$38)*I6+Inputs!$B$38*$B$32*$M6*$M$12 -> 0.0054234504 | J42: =(1-Inputs!$B$38)*J6+Inputs!$B$38*$B$32*$M6*$M$13 -> 4.8879317e-05 | K42: =(1-Inputs!$B$38)*K6+Inputs!$B$38*$B$32*$M6*$M$14 -> -0.00023173941 | L42: =(1-Inputs!$B$38)*L6+Inputs!$B$38*$B$32*$M6*$M$15 -> -0.00017249841 | M42: =SQRT(C42) -> 0.12748315
A43: Emerging Markets | B43: =(1-Inputs!$B$38)*B7+Inputs!$B$38*$B$32*$M7*$M$5 -> 0.0066781543 | C43: =(1-Inputs!$B$38)*C7+Inputs!$B$38*$B$32*$M7*$M$6 -> 0.0064462389 | D43: =D7 -> 0.011023027 | E43: =(1-Inputs!$B$38)*E7+Inputs!$B$38*$B$32*$M7*$M$8 -> 0.0050300231 | F43: =(1-Inputs!$B$38)*F7+Inputs!$B$38*$B$32*$M7*$M$9 -> 0.0042419457 | G43: =(1-Inputs!$B$38)*G7+Inputs!$B$38*$B$32*$M7*$M$10 -> 0.0030676732 | H43: =(1-Inputs!$B$38)*H7+Inputs!$B$38*$B$32*$M7*$M$11 -> 0.00022602456 | I43: =(1-Inputs!$B$38)*I7+Inputs!$B$38*$B$32*$M7*$M$12 -> 0.0031016595 | J43: =(1-Inputs!$B$38)*J7+Inputs!$B$38*$B$32*$M7*$M$13 -> -0.00020417593 | K43: =(1-Inputs!$B$38)*K7+Inputs!$B$38*$B$32*$M7*$M$14 -> -6.0011145e-05 | L43: =(1-Inputs!$B$38)*L7+Inputs!$B$38*$B$32*$M7*$M$15 -> -8.0693182e-05 | M43: =SQRT(D43) -> 0.1049906
A44: Listed Property | B44: =(1-Inputs!$B$38)*B8+Inputs!$B$38*$B$32*$M8*$M$5 -> 0.0082034018 | C44: =(1-Inputs!$B$38)*C8+Inputs!$B$38*$B$32*$M8*$M$6 -> 0.010304398 | D44: =(1-Inputs!$B$38)*D8+Inputs!$B$38*$B$32*$M8*$M$7 -> 0.0050300231 | E44: =E8 -> 0.028110729 | F44: =(1-Inputs!$B$38)*F8+Inputs!$B$38*$B$32*$M8*$M$9 -> 0.0035948614 | G44: =(1-Inputs!$B$38)*G8+Inputs!$B$38*$B$32*$M8*$M$10 -> 0.001648462 | H44: =(1-Inputs!$B$38)*H8+Inputs!$B$38*$B$32*$M8*$M$11 -> -0.00085158795 | I44: =(1-Inputs!$B$38)*I8+Inputs!$B$38*$B$32*$M8*$M$12 -> 0.005708351 | J44: =(1-Inputs!$B$38)*J8+Inputs!$B$38*$B$32*$M8*$M$13 -> 0.00099428356 | K44: =(1-Inputs!$B$38)*K8+Inputs!$B$38*$B$32*$M8*$M$14 -> 0.00098437353 | L44: =(1-Inputs!$B$38)*L8+Inputs!$B$38*$B$32*$M8*$M$15 -> -0.0001351391 | M44: =SQRT(E44) -> 0.16766255
A45: Commodities | B45: =(1-Inputs!$B$38)*B9+Inputs!$B$38*$B$32*$M9*$M$5 -> 0.007417201 | C45: =(1-Inputs!$B$38)*C9+Inputs!$B$38*$B$32*$M9*$M$6 -> 0.0050216726 | D45: =(1-Inputs!$B$38)*D9+Inputs!$B$38*$B$32*$M9*$M$7 -> 0.0042419457 | E45: =(1-Inputs!$B$38)*E9+Inputs!$B$38*$B$32*$M9*$M$8 -> 0.0035948614 | F45: =F9 -> 0.060457147 | G45: =(1-Inputs!$B$38)*G9+Inputs!$B$38*$B$32*$M9*$M$10 -> 0.003971938 | H45: =(1-Inputs!$B$38)*H9+Inputs!$B$38*$B$32*$M9*$M$11 -> -0.0012948877 | I45: =(1-Inputs!$B$38)*I9+Inputs!$B$38*$B$32*$M9*$M$12 -> 0.0009218478 | J45: =(1-Inputs!$B$38)*J9+Inputs!$B$38*$B$32*$M9*$M$13 -> -0.0031876817 | K45: =(1-Inputs!$B$38)*K9+Inputs!$B$38*$B$32*$M9*$M$14 -> -0.0032125647 | L45: =(1-Inputs!$B$38)*L9+Inputs!$B$38*$B$32*$M9*$M$15 -> -0.0001132026 | M45: =SQRT(F45) -> 0.24588035
A46: Direct Property | B46: =(1-Inputs!$B$38)*B10+Inputs!$B$38*$B$32*$M10*$M$5 -> 0.0025747826 | C46: =(1-Inputs!$B$38)*C10+Inputs!$B$38*$B$32*$M10*$M$6 -> 0.0026664933 | D46: =(1-Inputs!$B$38)*D10+Inputs!$B$38*$B$32*$M10*$M$7 -> 0.0030676732 | E46: =(1-Inputs!$B$38)*E10+Inputs!$B$38*$B$32*$M10*$M$8 -> 0.001648462 | F46: =(1-Inputs!$B$38)*F10+Inputs!$B$38*$B$32*$M10*$M$9 -> 0.003971938 | G46: =G10 -> 0.0090884856 | H46: =(1-Inputs!$B$38)*H10+Inputs!$B$38*$B$32*$M10*$M$11 -> 0.00050752368 | I46: =(1-Inputs!$B$38)*I10+Inputs!$B$38*$B$32*$M10*$M$12 -> 0.0019412087 | J46: =(1-Inputs!$B$38)*J10+Inputs!$B$38*$B$32*$M10*$M$13 -> -0.00058120664 | K46: =(1-Inputs!$B$38)*K10+Inputs!$B$38*$B$32*$M10*$M$14 -> -0.00030070344 | L46: =(1-Inputs!$B$38)*L10+Inputs!$B$38*$B$32*$M10*$M$15 -> -5.2311367e-05 | M46: =SQRT(G46) -> 0.095333549
A47: Hedge Funds | B47: =(1-Inputs!$B$38)*B11+Inputs!$B$38*$B$32*$M11*$M$5 -> -0.00097168636 | C47: =(1-Inputs!$B$38)*C11+Inputs!$B$38*$B$32*$M11*$M$6 -> 0.00015549994 | D47: =(1-Inputs!$B$38)*D11+Inputs!$B$38*$B$32*$M11*$M$7 -> 0.00022602456 | E47: =(1-Inputs!$B$38)*E11+Inputs!$B$38*$B$32*$M11*$M$8 -> -0.00085158795 | F47: =(1-Inputs!$B$38)*F11+Inputs!$B$38*$B$32*$M11*$M$9 -> -0.0012948877 | G47: =(1-Inputs!$B$38)*G11+Inputs!$B$38*$B$32*$M11*$M$10 -> 0.00050752368 | H47: =H11 -> 0.0051752768 | I47: =(1-Inputs!$B$38)*I11+Inputs!$B$38*$B$32*$M11*$M$12 -> -8.6973008e-05 | J47: =(1-Inputs!$B$38)*J11+Inputs!$B$38*$B$32*$M11*$M$13 -> 0.00033693012 | K47: =(1-Inputs!$B$38)*K11+Inputs!$B$38*$B$32*$M11*$M$14 -> 0.00010628647 | L47: =(1-Inputs!$B$38)*L11+Inputs!$B$38*$B$32*$M11*$M$15 -> 9.215266e-05 | M47: =SQRT(H47) -> 0.071939397
A48: Private Equity | B48: =(1-Inputs!$B$38)*B12+Inputs!$B$38*$B$32*$M12*$M$5 -> 0.0075237358 | C48: =(1-Inputs!$B$38)*C12+Inputs!$B$38*$B$32*$M12*$M$6 -> 0.0054234504 | D48: =(1-Inputs!$B$38)*D12+Inputs!$B$38*$B$32*$M12*$M$7 -> 0.0031016595 | E48: =(1-Inputs!$B$38)*E12+Inputs!$B$38*$B$32*$M12*$M$8 -> 0.005708351 | F48: =(1-Inputs!$B$38)*F12+Inputs!$B$38*$B$32*$M12*$M$9 -> 0.0009218478 | G48: =(1-Inputs!$B$38)*G12+Inputs!$B$38*$B$32*$M12*$M$10 -> 0.0019412087 | H48: =(1-Inputs!$B$38)*H12+Inputs!$B$38*$B$32*$M12*$M$11 -> -8.6973008e-05 | I48: =I12 -> 0.01619156 | J48: =(1-Inputs!$B$38)*J12+Inputs!$B$38*$B$32*$M12*$M$13 -> 0.00040436974 | K48: =(1-Inputs!$B$38)*K12+Inputs!$B$38*$B$32*$M12*$M$14 -> 0.00045580044 | L48: =(1-Inputs!$B$38)*L12+Inputs!$B$38*$B$32*$M12*$M$15 -> -4.5947589e-05 | M48: =SQRT(I48) -> 0.12724606
A49: Australian Fixed Income | B49: =(1-Inputs!$B$38)*B13+Inputs!$B$38*$B$32*$M13*$M$5 -> -0.00046316007 | C49: =(1-Inputs!$B$38)*C13+Inputs!$B$38*$B$32*$M13*$M$6 -> 4.8879317e-05 | D49: =(1-Inputs!$B$38)*D13+Inputs!$B$38*$B$32*$M13*$M$7 -> -0.00020417593 | E49: =(1-Inputs!$B$38)*E13+Inputs!$B$38*$B$32*$M13*$M$8 -> 0.00099428356 | F49: =(1-Inputs!$B$38)*F13+Inputs!$B$38*$B$32*$M13*$M$9 -> -0.0031876817 | G49: =(1-Inputs!$B$38)*G13+Inputs!$B$38*$B$32*$M13*$M$10 -> -0.00058120664 | H49: =(1-Inputs!$B$38)*H13+Inputs!$B$38*$B$32*$M13*$M$11 -> 0.00033693012 | I49: =(1-Inputs!$B$38)*I13+Inputs!$B$38*$B$32*$M13*$M$12 -> 0.00040436974 | J49: =J13 -> 0.0018053161 | K49: =(1-Inputs!$B$38)*K13+Inputs!$B$38*$B$32*$M13*$M$14 -> 0.00097215318 | L49: =(1-Inputs!$B$38)*L13+Inputs!$B$38*$B$32*$M13*$M$15 -> 0.00011059713 | M49: =SQRT(J49) -> 0.042489011
A50: World Fixed Income | B50: =(1-Inputs!$B$38)*B14+Inputs!$B$38*$B$32*$M14*$M$5 -> 0.00033345657 | C50: =(1-Inputs!$B$38)*C14+Inputs!$B$38*$B$32*$M14*$M$6 -> -0.00023173941 | D50: =(1-Inputs!$B$38)*D14+Inputs!$B$38*$B$32*$M14*$M$7 -> -6.0011145e-05 | E50: =(1-Inputs!$B$38)*E14+Inputs!$B$38*$B$32*$M14*$M$8 -> 0.00098437353 | F50: =(1-Inputs!$B$38)*F14+Inputs!$B$38*$B$32*$M14*$M$9 -> -0.0032125647 | G50: =(1-Inputs!$B$38)*G14+Inputs!$B$38*$B$32*$M14*$M$10 -> -0.00030070344 | H50: =(1-Inputs!$B$38)*H14+Inputs!$B$38*$B$32*$M14*$M$11 -> 0.00010628647 | I50: =(1-Inputs!$B$38)*I14+Inputs!$B$38*$B$32*$M14*$M$12 -> 0.00045580044 | J50: =(1-Inputs!$B$38)*J14+Inputs!$B$38*$B$32*$M14*$M$13 -> 0.00097215318 | K50: =K14 -> 0.0016427464 | L50: =(1-Inputs!$B$38)*L14+Inputs!$B$38*$B$32*$M14*$M$15 -> 0.00010324317 | M50: =SQRT(K50) -> 0.040530808
...

Sheet Portfolio
A1: Portfolio
A3: 1. Stage 1 (optimised) and Stage 2 (judgement)
A5: Asset class | B5: Stage | C5: Current | D5: Benchmark | E5: Recommended | F5: Lower | G5: Upper | H5: Active vs benchmark | I5: Change vs current | J5: Trade (A$m) | K5: Net forecast (arithmetic) | L5: Return contribution
A6: Australian Equities | B6: 1: optimised | C6: =Inputs!B5 -> 0.4 | D6: =Inputs!C5 -> 0.25 | E6: =Methods!I6 -> 0.2738 | F6: =Inputs!E5 -> 0.15 | G6: =Inputs!F5 -> 0.35 | H6: =E6-D6 -> 0.0238 | I6: =E6-C6 -> -0.1262 | J6: =I6*Inputs!$B$22 -> -378.6 | K6: =Forecast!G6 -> 0.077798125 | L6: =E6*K6 -> 0.021301127
A7: World Equities | B7: 1: optimised | C7: =Inputs!B6 -> 0.2 | D7: =Inputs!C6 -> 0.24 | E7: =Methods!I7 -> 0.279 | F7: =Inputs!E6 -> 0.15 | G7: =Inputs!F6 -> 0.35 | H7: =E7-D7 -> 0.039 | I7: =E7-C7 -> 0.079 | J7: =I7*Inputs!$B$22 -> 237 | K7: =Forecast!G7 -> 0.077298125 | L7: =E7*K7 -> 0.021566177
A8: Emerging Markets | B8: 1: optimised | C8: =Inputs!B7 -> 0 | D8: =Inputs!C7 -> 0.03 | E8: =Methods!I8 -> 0.0672 | F8: =Inputs!E7 -> 0 | G8: =Inputs!F7 -> 0.08 | H8: =E8-D8 -> 0.0372 | I8: =E8-C8 -> 0.0672 | J8: =I8*Inputs!$B$22 -> 201.6 | K8: =Forecast!G8 -> 0.070695109 | L8: =E8*K8 -> 0.0047507113
A9: Listed Property | B9: 1: optimised | C9: =Inputs!B8 -> 0.1 | D9: =Inputs!C8 -> 0.07 | E9: =Methods!I9 -> 0.0867 | F9: =Inputs!E8 -> 0 | G9: =Inputs!F8 -> 0.12 | H9: =E9-D9 -> 0.0167 | I9: =E9-C9 -> -0.0133 | J9: =I9*Inputs!$B$22 -> -39.9 | K9: =Forecast!G9 -> 0.079125486 | L9: =E9*K9 -> 0.0068601796
A10: Commodities | B10: 2: optimised | C10: =Inputs!B9 -> 0 | D10: =Inputs!C9 -> 0.02 | E10: =Methods!I10 -> 0.0244 | F10: =Inputs!E9 -> 0 | G10: =Inputs!F9 -> 0.08 | H10: =E10-D10 -> 0.0044 | I10: =E10-C10 -> 0.0244 | J10: =I10*Inputs!$B$22 -> 73.2 | K10: =Forecast!G10 -> 0.069904767 | L10: =E10*K10 -> 0.0017056763
A11: Direct Property | B11: 2: optimised | C11: =Inputs!B10 -> 0 | D11: =Inputs!C10 -> 0.05 | E11: =Methods!I11 -> 0 | F11: =Inputs!E10 -> 0 | G11: =Inputs!F10 -> 0.1 | H11: =E11-D11 -> -0.05 | I11: =E11-C11 -> 0 | J11: =I11*Inputs!$B$22 -> 0 | K11: =Forecast!G11 -> 0.044224902 | L11: =E11*K11 -> 0
A12: Hedge Funds | B12: 2: optimised | C12: =Inputs!B11 -> 0 | D12: =Inputs!C11 -> 0.03 | E12: =Methods!I12 -> 0 | F12: =Inputs!E11 -> 0 | G12: =Inputs!F11 -> 0.08 | H12: =E12-D12 -> -0.03 | I12: =E12-C12 -> 0 | J12: =I12*Inputs!$B$22 -> 0 | K12: =Forecast!G12 -> 0.037272538 | L12: =E12*K12 -> 0
A13: Private Equity | B13: 2: optimised | C13: =Inputs!B12 -> 0 | D13: =Inputs!C12 -> 0.03 | E13: =Methods!I13 -> 0 | F13: =Inputs!E12 -> 0 | G13: =Inputs!F12 -> 0.08 | H13: =E13-D13 -> -0.03 | I13: =E13-C13 -> 0 | J13: =I13*Inputs!$B$22 -> 0 | K13: =Forecast!G13 -> 0.051506021 | L13: =E13*K13 -> 0
A14: Australian Fixed Income | B14: 1: optimised | C14: =Inputs!B13 -> 0.15 | D14: =Inputs!C13 -> 0.14 | E14: =Methods!I14 -> 0.12 | F14: =Inputs!E13 -> 0.12 | G14: =Inputs!F13 -> 0.25 | H14: =E14-D14 -> -0.02 | I14: =E14-C14 -> -0.03 | J14: =I14*Inputs!$B$22 -> -90 | K14: =Forecast!G14 -> 0.050204912 | L14: =E14*K14 -> 0.0060245894
A15: World Fixed Income | B15: 1: optimised | C15: =Inputs!B14 -> 0.08 | D15: =Inputs!C14 -> 0.11 | E15: =Methods!I15 -> 0.1289 | F15: =Inputs!E14 -> 0.05 | G15: =Inputs!F14 -> 0.2 | H15: =E15-D15 -> 0.0189 | I15: =E15-C15 -> 0.0489 | J15: =I15*Inputs!$B$22 -> 146.7 | K15: =Forecast!G15 -> 0.053294643 | L15: =E15*K15 -> 0.0068696795
A16: Cash | B16: 1: optimised | C16: =Inputs!B15 -> 0.07 | D16: =Inputs!C15 -> 0.03 | E16: =Methods!I16 -> 0.02 | F16: =Inputs!E15 -> 0.02 | G16: =Inputs!F15 -> 0.1 | H16: =E16-D16 -> -0.01 | I16: =E16-C16 -> -0.05 | J16: =I16*Inputs!$B$22 -> -150 | K16: =Forecast!G16 -> 0.047698326 | L16: =E16*K16 -> 0.00095396652
A17: Total | C17: =SUM(C6:C16) -> 1 | D17: =SUM(D6:D16) -> 1 | E17: =SUM(E6:E16) -> 1 | H17: =SUM(H6:H16) -> 0 | I17: =SUM(I6:I16) -> 0 | J17: =SUM(J6:J16) -> 0 | L17: =SUM(L6:L16) -> 0.070032106
A20: 2. Stage 2 scorecard (1 to 5): cross-check on the optimised alternatives weights
A22: Asset class | B22: Return | C22: Diversification | D22: Liquidity | E22: Data quality | F22: Implementation | G22: Average | H22: Optimised weight | I22: Benchmark
A23: Commodities | B23: 3 | C23: 5 | D23: 5 | E23: 3 | F23: 4 | G23: =AVERAGE(B23:F23) -> 4 | H23: =E10 -> 0.0244 | I23: =Inputs!C9 -> 0.02
A24: Direct Property | B24: 3 | C24: 4 | D24: 1 | E24: 2 | F24: 2 | G24: =AVERAGE(B24:F24) -> 2.4 | H24: =E11 -> 0 | I24: =Inputs!C10 -> 0.05
A25: Hedge Funds | B25: 2 | C25: 3 | D25: 2 | E25: 2 | F25: 2 | G25: =AVERAGE(B25:F25) -> 2.2 | H25: =E12 -> 0 | I25: =Inputs!C11 -> 0.03
A26: Private Equity | B26: 4 | C26: 3 | D26: 1 | E26: 2 | F26: 2 | G26: =AVERAGE(B26:F26) -> 2.4 | H26: =E13 -> 0 | I26: =Inputs!C12 -> 0.03
A27: Total Stage 2 | H27: =SUM(H23:H26) -> 0.0244 | I27: =SUM(I23:I26) -> 0.13
A30: 3. Solver constraints
A31: Metric | B31: Value | C31: Lower limit | D31: Upper limit | E31: Status
A32: Expected return, arithmetic (maximise) | B32: =SUMPRODUCT(E6:E16,K6:K16) -> 0.070032106 | E32: ="INFO" -> INFO
A33: Tracking error (parametric) | B33: =Risk!O58 -> 0.011002382 | D33: =Inputs!$B$45 -> 0.011 | E33: =IF(B33<=D33+0.00005,"MET","NOT MET") -> MET
A34: Equity allocation | B34: =SUMPRODUCT(E6:E16,Inputs!$G$5:$G$15) -> 0.62 | C34: =Inputs!$B$31 -> 0.42 | D34: =Inputs!$B$32 -> 0.62 | E34: =IF(AND(B34>=C34-0.000001,B34<=D34+0.000001),"MET","NOT MET") -> MET
A35: Illiquid allocation | B35: =SUMPRODUCT(E6:E16,Inputs!$H$5:$H$15) -> 0 | D35: =Inputs!$B$33 -> 0.3 | E35: =IF(B35<=D35,"MET","NOT MET") -> MET
A36: Cash allocation | B36: =E16 -> 0.02 | C36: =Inputs!$B$34 -> 0.02 | E36: =IF(B36>=C36,"MET","NOT MET") -> MET
A37: Weights sum to 100% | B37: =SUM(E6:E16) -> 1 | C37: 1 | D37: 1 | E37: =IF(ABS(B37-1)<0.000001,"MET","NOT MET") -> MET
A38: Share inside bounds | B38: =SUMPRODUCT((E6:E16>=F6:F16-0.000001)*(E6:E16<=G6:G16+0.000001))/11 -> 1 | C38: 1 | E38: =IF(B38>=C38,"MET","NOT MET") -> MET
A41: 4. What each constraint costs
A42: Asset class | B42: Base (recommended) | C42: TE limit 1.5% | D42: No TE limit | E42: Equity max 72% | F42: Alternatives fixed by scorecard | G42: Long-only only
A43: Australian Equities | B43: =E6 -> 0.2738 | C43: 0.2803 | D43: 0.35 | E43: 0.274 | F43: 0.2722 | G43: 0
A44: World Equities | B44: =E7 -> 0.279 | C44: 0.2809 | D44: 0.27 | E44: 0.2798 | F44: 0.2749 | G44: 0
A45: Emerging Markets | B45: =E8 -> 0.0672 | C45: 0.0588 | D45: 0 | E45: 0.0685 | F45: 0.0547 | G45: 0
A46: Listed Property | B46: =E9 -> 0.0867 | C46: 0.1165 | D46: 0.12 | E46: 0.0852 | F46: 0.09 | G46: 0.98
A47: Commodities | B47: =E10 -> 0.0244 | C47: 0.0292 | D47: 0.07 | E47: 0.024 | F47: 0.03 | G47: 0
A48: Direct Property | B48: =E11 -> 0 | C48: 0 | D48: 0 | E48: 0 | F48: 0.05 | G48: 0
A49: Hedge Funds | B49: =E12 -> 0 | C49: 0 | D49: 0 | E49: 0 | F49: 0 | G49: 0
...

Sheet Methods
A1: Methods
A2: Selected method | B2: =INDEX(D5:H5,Inputs!$B$49) -> Robust MVO
A3: 1. Method weights (alternatives optimised; Australian fixed income floor 12%; risk parity holds the scorecard alternatives)
A5: Asset class | B5: Current | C5: Benchmark | D5: Robust MVO | E5: Sample MVO | F5: Resampled MVO | G5: Minimum variance | H5: Risk parity | I5: Selected
